[2023-08-31T03:55:28.286+0000] {taskinstance.py:1103} INFO - Dependencies all met for dep_context=non-requeueable deps ti=<TaskInstance: process_sale_data.log_info manual__2023-08-31T03:55:20.596452+00:00 [queued]>
[2023-08-31T03:55:28.294+0000] {taskinstance.py:1103} INFO - Dependencies all met for dep_context=requeueable deps ti=<TaskInstance: process_sale_data.log_info manual__2023-08-31T03:55:20.596452+00:00 [queued]>
[2023-08-31T03:55:28.294+0000] {taskinstance.py:1308} INFO - Starting attempt 1 of 1
[2023-08-31T03:55:28.308+0000] {taskinstance.py:1327} INFO - Executing <Task(PythonOperator): log_info> on 2023-08-31 03:55:20.596452+00:00
[2023-08-31T03:55:28.312+0000] {standard_task_runner.py:57} INFO - Started process 5834 to run task
[2023-08-31T03:55:28.315+0000] {standard_task_runner.py:84} INFO - Running: ['***', 'tasks', 'run', 'process_sale_data', 'log_info', 'manual__2023-08-31T03:55:20.596452+00:00', '--job-id', '179', '--raw', '--subdir', 'DAGS_FOLDER/dags.py', '--cfg-path', '/tmp/tmp2fxpgeyf']
[2023-08-31T03:55:28.318+0000] {standard_task_runner.py:85} INFO - Job 179: Subtask log_info
[2023-08-31T03:55:28.359+0000] {task_command.py:410} INFO - Running <TaskInstance: process_sale_data.log_info manual__2023-08-31T03:55:20.596452+00:00 [running]> on host 888526fa4a36
[2023-08-31T03:55:28.546+0000] {taskinstance.py:1547} INFO - Exporting env vars: AIRFLOW_CTX_DAG_OWNER='***' AIRFLOW_CTX_DAG_ID='process_sale_data' AIRFLOW_CTX_TASK_ID='log_info' AIRFLOW_CTX_EXECUTION_DATE='2023-08-31T03:55:20.596452+00:00' AIRFLOW_CTX_TRY_NUMBER='1' AIRFLOW_CTX_DAG_RUN_ID='manual__2023-08-31T03:55:20.596452+00:00'
[2023-08-31T03:55:28.727+0000] {taskinstance.py:1824} ERROR - Task failed with exception
Traceback (most recent call last):
  File "/home/airflow/.local/lib/python3.7/site-packages/airflow/operators/python.py", line 181, in execute
    return_value = self.execute_callable()
  File "/home/airflow/.local/lib/python3.7/site-packages/airflow/operators/python.py", line 198, in execute_callable
    return self.python_callable(*self.op_args, **self.op_kwargs)
  File "/opt/airflow/dags/py_callables.py", line 95, in log_task_info
    for instance in ti.get_dagrun().get_task_instance():
  File "/home/airflow/.local/lib/python3.7/site-packages/airflow/utils/session.py", line 76, in wrapper
    return func(*args, session=session, **kwargs)
TypeError: get_task_instance() missing 1 required positional argument: 'task_id'
[2023-08-31T03:55:28.743+0000] {taskinstance.py:1350} INFO - Marking task as FAILED. dag_id=process_sale_data, task_id=log_info, execution_date=20230831T035520, start_date=20230831T035528, end_date=20230831T035528
[2023-08-31T03:55:28.758+0000] {standard_task_runner.py:109} ERROR - Failed to execute job 179 for task log_info (get_task_instance() missing 1 required positional argument: 'task_id'; 5834)
[2023-08-31T03:55:28.769+0000] {local_task_job_runner.py:225} INFO - Task exited with return code 1
[2023-08-31T03:55:28.786+0000] {taskinstance.py:2653} INFO - 0 downstream tasks scheduled from follow-on schedule check
