[2023-08-31T02:59:40.384+0000] {taskinstance.py:1103} INFO - Dependencies all met for dep_context=non-requeueable deps ti=<TaskInstance: process_sale_data.validate_result manual__2023-08-31T02:59:39.361482+00:00 [queued]>
[2023-08-31T02:59:40.391+0000] {taskinstance.py:1103} INFO - Dependencies all met for dep_context=requeueable deps ti=<TaskInstance: process_sale_data.validate_result manual__2023-08-31T02:59:39.361482+00:00 [queued]>
[2023-08-31T02:59:40.392+0000] {taskinstance.py:1308} INFO - Starting attempt 1 of 1
[2023-08-31T02:59:40.405+0000] {taskinstance.py:1327} INFO - Executing <Task(PythonOperator): validate_result> on 2023-08-31 02:59:39.361482+00:00
[2023-08-31T02:59:40.409+0000] {standard_task_runner.py:57} INFO - Started process 3072 to run task
[2023-08-31T02:59:40.411+0000] {standard_task_runner.py:84} INFO - Running: ['***', 'tasks', 'run', 'process_sale_data', 'validate_result', 'manual__2023-08-31T02:59:39.361482+00:00', '--job-id', '145', '--raw', '--subdir', 'DAGS_FOLDER/dags.py', '--cfg-path', '/tmp/tmp7o01rihn']
[2023-08-31T02:59:40.415+0000] {standard_task_runner.py:85} INFO - Job 145: Subtask validate_result
[2023-08-31T02:59:40.457+0000] {task_command.py:410} INFO - Running <TaskInstance: process_sale_data.validate_result manual__2023-08-31T02:59:39.361482+00:00 [running]> on host 888526fa4a36
[2023-08-31T02:59:40.534+0000] {taskinstance.py:1547} INFO - Exporting env vars: AIRFLOW_CTX_DAG_OWNER='***' AIRFLOW_CTX_DAG_ID='process_sale_data' AIRFLOW_CTX_TASK_ID='validate_result' AIRFLOW_CTX_EXECUTION_DATE='2023-08-31T02:59:39.361482+00:00' AIRFLOW_CTX_TRY_NUMBER='1' AIRFLOW_CTX_DAG_RUN_ID='manual__2023-08-31T02:59:39.361482+00:00'
[2023-08-31T02:59:40.540+0000] {base.py:73} INFO - Using connection ID 'postgres' for task execution.
[2023-08-31T02:59:40.544+0000] {sql.py:375} INFO - Running statement: SELECT COUNT(*) FROM consumption_alcoholic_20230831, parameters: None
[2023-08-31T02:59:40.545+0000] {sql.py:384} INFO - Rows affected: 1
[2023-08-31T02:59:40.553+0000] {base.py:73} INFO - Using connection ID 'postgres' for task execution.
[2023-08-31T02:59:40.555+0000] {sql.py:375} INFO - Running statement: SELECT COUNT(*) FROM consumption_cereals_bakery_20230831, parameters: None
[2023-08-31T02:59:40.557+0000] {sql.py:384} INFO - Rows affected: 1
[2023-08-31T02:59:40.693+0000] {base.py:73} INFO - Using connection ID 'postgres' for task execution.
[2023-08-31T02:59:40.699+0000] {sql.py:375} INFO - Running statement: SELECT COUNT(*) FROM consumption_meats_poultry_20230831, parameters: None
[2023-08-31T02:59:40.701+0000] {sql.py:384} INFO - Rows affected: 1
[2023-08-31T02:59:40.726+0000] {taskinstance.py:1824} ERROR - Task failed with exception
Traceback (most recent call last):
  File "/home/airflow/.local/lib/python3.7/site-packages/airflow/operators/python.py", line 181, in execute
    return_value = self.execute_callable()
  File "/home/airflow/.local/lib/python3.7/site-packages/airflow/operators/python.py", line 198, in execute_callable
    return self.python_callable(*self.op_args, **self.op_kwargs)
  File "/opt/airflow/dags/py_callables.py", line 87, in validate_result
    .format(meat_poultry_tbl_rows = meat_poultry_tbl_rows, meat_poultry_file_rows = meat_poultry_file_rows))
airflow.exceptions.AirflowFailException: Error: number of rows in meat and poultry tables: 2980 don't match with file input: 2980
[2023-08-31T02:59:40.740+0000] {taskinstance.py:1350} INFO - Immediate failure requested. Marking task as FAILED. dag_id=process_sale_data, task_id=validate_result, execution_date=20230831T025939, start_date=20230831T025940, end_date=20230831T025940
[2023-08-31T02:59:40.752+0000] {standard_task_runner.py:109} ERROR - Failed to execute job 145 for task validate_result (Error: number of rows in meat and poultry tables: 2980 don't match with file input: 2980; 3072)
[2023-08-31T02:59:40.785+0000] {local_task_job_runner.py:225} INFO - Task exited with return code 1
[2023-08-31T02:59:40.797+0000] {taskinstance.py:2653} INFO - 0 downstream tasks scheduled from follow-on schedule check
