[2023-08-30T06:55:04.083+0000] {taskinstance.py:1103} INFO - Dependencies all met for dep_context=non-requeueable deps ti=<TaskInstance: process_sale_data.check_file_exist manual__2023-08-30T06:55:03.063755+00:00 [queued]>
[2023-08-30T06:55:04.093+0000] {taskinstance.py:1103} INFO - Dependencies all met for dep_context=requeueable deps ti=<TaskInstance: process_sale_data.check_file_exist manual__2023-08-30T06:55:03.063755+00:00 [queued]>
[2023-08-30T06:55:04.093+0000] {taskinstance.py:1308} INFO - Starting attempt 1 of 1
[2023-08-30T06:55:04.108+0000] {taskinstance.py:1327} INFO - Executing <Task(PythonOperator): check_file_exist> on 2023-08-30 06:55:03.063755+00:00
[2023-08-30T06:55:04.112+0000] {standard_task_runner.py:57} INFO - Started process 281 to run task
[2023-08-30T06:55:04.115+0000] {standard_task_runner.py:84} INFO - Running: ['***', 'tasks', 'run', 'process_sale_data', 'check_file_exist', 'manual__2023-08-30T06:55:03.063755+00:00', '--job-id', '28', '--raw', '--subdir', 'DAGS_FOLDER/dags.py', '--cfg-path', '/tmp/tmp0k1dmfc0']
[2023-08-30T06:55:04.117+0000] {standard_task_runner.py:85} INFO - Job 28: Subtask check_file_exist
[2023-08-30T06:55:04.174+0000] {task_command.py:410} INFO - Running <TaskInstance: process_sale_data.check_file_exist manual__2023-08-30T06:55:03.063755+00:00 [running]> on host 888526fa4a36
[2023-08-30T06:55:04.244+0000] {taskinstance.py:1547} INFO - Exporting env vars: AIRFLOW_CTX_DAG_OWNER='***' AIRFLOW_CTX_DAG_ID='process_sale_data' AIRFLOW_CTX_TASK_ID='check_file_exist' AIRFLOW_CTX_EXECUTION_DATE='2023-08-30T06:55:03.063755+00:00' AIRFLOW_CTX_TRY_NUMBER='1' AIRFLOW_CTX_DAG_RUN_ID='manual__2023-08-30T06:55:03.063755+00:00'
[2023-08-30T06:55:04.245+0000] {logging_mixin.py:149} INFO - File not found, try again in 5 minutes
[2023-08-30T06:59:26.114+0000] {local_task_job_runner.py:292} WARNING - State of this instance has been externally set to failed. Terminating instance.
[2023-08-30T06:59:26.116+0000] {process_utils.py:135} INFO - Sending Signals.SIGTERM to group 281. PIDs of all processes in the group: [281]
[2023-08-30T06:59:26.116+0000] {process_utils.py:86} INFO - Sending the signal Signals.SIGTERM to group 281
[2023-08-30T06:59:26.117+0000] {taskinstance.py:1517} ERROR - Received SIGTERM. Terminating subprocesses.
[2023-08-30T06:59:26.144+0000] {process_utils.py:79} INFO - Process psutil.Process(pid=281, status='terminated', exitcode=0, started='06:55:03') (281) terminated with exit code 0
