[2023-08-31T04:01:07.432+0000] {taskinstance.py:1103} INFO - Dependencies all met for dep_context=non-requeueable deps ti=<TaskInstance: process_sale_data.log_info manual__2023-08-31T04:01:00.587441+00:00 [queued]>
[2023-08-31T04:01:07.440+0000] {taskinstance.py:1103} INFO - Dependencies all met for dep_context=requeueable deps ti=<TaskInstance: process_sale_data.log_info manual__2023-08-31T04:01:00.587441+00:00 [queued]>
[2023-08-31T04:01:07.440+0000] {taskinstance.py:1308} INFO - Starting attempt 1 of 1
[2023-08-31T04:01:07.456+0000] {taskinstance.py:1327} INFO - Executing <Task(PythonOperator): log_info> on 2023-08-31 04:01:00.587441+00:00
[2023-08-31T04:01:07.461+0000] {standard_task_runner.py:57} INFO - Started process 6123 to run task
[2023-08-31T04:01:07.466+0000] {standard_task_runner.py:84} INFO - Running: ['***', 'tasks', 'run', 'process_sale_data', 'log_info', 'manual__2023-08-31T04:01:00.587441+00:00', '--job-id', '185', '--raw', '--subdir', 'DAGS_FOLDER/dags.py', '--cfg-path', '/tmp/tmpgv_hvu3e']
[2023-08-31T04:01:07.468+0000] {standard_task_runner.py:85} INFO - Job 185: Subtask log_info
[2023-08-31T04:01:07.510+0000] {task_command.py:410} INFO - Running <TaskInstance: process_sale_data.log_info manual__2023-08-31T04:01:00.587441+00:00 [running]> on host 888526fa4a36
[2023-08-31T04:01:07.586+0000] {taskinstance.py:1547} INFO - Exporting env vars: AIRFLOW_CTX_DAG_OWNER='***' AIRFLOW_CTX_DAG_ID='process_sale_data' AIRFLOW_CTX_TASK_ID='log_info' AIRFLOW_CTX_EXECUTION_DATE='2023-08-31T04:01:00.587441+00:00' AIRFLOW_CTX_TRY_NUMBER='1' AIRFLOW_CTX_DAG_RUN_ID='manual__2023-08-31T04:01:00.587441+00:00'
[2023-08-31T04:01:07.727+0000] {taskinstance.py:1824} ERROR - Task failed with exception
Traceback (most recent call last):
  File "/home/airflow/.local/lib/python3.7/site-packages/airflow/operators/python.py", line 181, in execute
    return_value = self.execute_callable()
  File "/home/airflow/.local/lib/python3.7/site-packages/airflow/operators/python.py", line 198, in execute_callable
    return self.python_callable(*self.op_args, **self.op_kwargs)
  File "/opt/airflow/dags/py_callables.py", line 96, in log_task_info
    if instance.duration > max_task_duration:
TypeError: '>' not supported between instances of 'NoneType' and 'float'
[2023-08-31T04:01:07.741+0000] {taskinstance.py:1350} INFO - Marking task as FAILED. dag_id=process_sale_data, task_id=log_info, execution_date=20230831T040100, start_date=20230831T040107, end_date=20230831T040107
[2023-08-31T04:01:07.754+0000] {standard_task_runner.py:109} ERROR - Failed to execute job 185 for task log_info ('>' not supported between instances of 'NoneType' and 'float'; 6123)
[2023-08-31T04:01:07.799+0000] {local_task_job_runner.py:225} INFO - Task exited with return code 1
[2023-08-31T04:01:07.827+0000] {taskinstance.py:2653} INFO - 0 downstream tasks scheduled from follow-on schedule check
