[2023-08-31T03:53:11.725+0000] {taskinstance.py:1103} INFO - Dependencies all met for dep_context=non-requeueable deps ti=<TaskInstance: process_sale_data.log_info manual__2023-08-31T03:53:03.900971+00:00 [queued]>
[2023-08-31T03:53:11.733+0000] {taskinstance.py:1103} INFO - Dependencies all met for dep_context=requeueable deps ti=<TaskInstance: process_sale_data.log_info manual__2023-08-31T03:53:03.900971+00:00 [queued]>
[2023-08-31T03:53:11.735+0000] {taskinstance.py:1308} INFO - Starting attempt 1 of 1
[2023-08-31T03:53:11.746+0000] {taskinstance.py:1327} INFO - Executing <Task(PythonOperator): log_info> on 2023-08-31 03:53:03.900971+00:00
[2023-08-31T03:53:11.752+0000] {standard_task_runner.py:57} INFO - Started process 5689 to run task
[2023-08-31T03:53:11.755+0000] {standard_task_runner.py:84} INFO - Running: ['***', 'tasks', 'run', 'process_sale_data', 'log_info', 'manual__2023-08-31T03:53:03.900971+00:00', '--job-id', '167', '--raw', '--subdir', 'DAGS_FOLDER/dags.py', '--cfg-path', '/tmp/tmpwimgcrhd']
[2023-08-31T03:53:11.757+0000] {standard_task_runner.py:85} INFO - Job 167: Subtask log_info
[2023-08-31T03:53:11.799+0000] {task_command.py:410} INFO - Running <TaskInstance: process_sale_data.log_info manual__2023-08-31T03:53:03.900971+00:00 [running]> on host 888526fa4a36
[2023-08-31T03:53:11.912+0000] {taskinstance.py:1547} INFO - Exporting env vars: AIRFLOW_CTX_DAG_OWNER='***' AIRFLOW_CTX_DAG_ID='process_sale_data' AIRFLOW_CTX_TASK_ID='log_info' AIRFLOW_CTX_EXECUTION_DATE='2023-08-31T03:53:03.900971+00:00' AIRFLOW_CTX_TRY_NUMBER='1' AIRFLOW_CTX_DAG_RUN_ID='manual__2023-08-31T03:53:03.900971+00:00'
[2023-08-31T03:53:12.052+0000] {taskinstance.py:1824} ERROR - Task failed with exception
Traceback (most recent call last):
  File "/home/airflow/.local/lib/python3.7/site-packages/airflow/operators/python.py", line 181, in execute
    return_value = self.execute_callable()
  File "/home/airflow/.local/lib/python3.7/site-packages/airflow/operators/python.py", line 198, in execute_callable
    return self.python_callable(*self.op_args, **self.op_kwargs)
  File "/opt/airflow/dags/py_callables.py", line 89, in log_task_info
    total_duration = datetime.datetime.strptime(end_date, "%Y/%m/%d %H:%M:%S") - datetime.datetime.strptime(exec_date, "%Y/%m/%d %H:%M:%S")
  File "/usr/local/lib/python3.7/_strptime.py", line 577, in _strptime_datetime
    tt, fraction, gmtoff_fraction = _strptime(data_string, format)
  File "/usr/local/lib/python3.7/_strptime.py", line 359, in _strptime
    (data_string, format))
ValueError: time data '20230831' does not match format '%Y/%m/%d %H:%M:%S'
[2023-08-31T03:53:12.066+0000] {taskinstance.py:1350} INFO - Marking task as FAILED. dag_id=process_sale_data, task_id=log_info, execution_date=20230831T035303, start_date=20230831T035311, end_date=20230831T035312
[2023-08-31T03:53:12.078+0000] {standard_task_runner.py:109} ERROR - Failed to execute job 167 for task log_info (time data '20230831' does not match format '%Y/%m/%d %H:%M:%S'; 5689)
[2023-08-31T03:53:12.089+0000] {local_task_job_runner.py:225} INFO - Task exited with return code 1
[2023-08-31T03:53:12.103+0000] {taskinstance.py:2653} INFO - 0 downstream tasks scheduled from follow-on schedule check
